"""error in naming relationship

Revision ID: 553c71c89182
Revises: ba5c7f80095d
Create Date: 2025-09-03 23:07:18.716266

"""
from alembic import op
import sqlalchemy as sa


# revision identifiers, used by Alembic.
revision = '553c71c89182'
down_revision = 'ba5c7f80095d'
branch_labels = None
depends_on = None


def upgrade():
    # ### commands auto generated by Alembic - please adjust! ###
    op.create_table('user',
    sa.Column('id', sa.Integer(), nullable=False),
    sa.Column('first_name', sa.String(length=100), nullable=False),
    sa.Column('last_name', sa.String(length=100), nullable=False),
    sa.Column('user_name', sa.String(length=100), nullable=False),
    sa.Column('password_hash', sa.String(length=128), nullable=False),
    sa.Column('created_at', sa.DateTime(), nullable=True),
    sa.PrimaryKeyConstraint('id'),
    sa.UniqueConstraint('user_name')
    )
    op.create_table('quizresult',
    sa.Column('id', sa.Integer(), nullable=False),
    sa.Column('quiz_score', sa.Integer(), nullable=True),
    sa.Column('created_at', sa.DateTime(), nullable=True),
    sa.Column('user_id', sa.Integer(), nullable=True),
    sa.ForeignKeyConstraint(['user_id'], ['user.id'], ),
    sa.PrimaryKeyConstraint('id')
    )
    op.drop_table('quiz_result')
    # ### end Alembic commands ###


def downgrade():
    # ### commands auto generated by Alembic - please adjust! ###
    op.create_table('quiz_result',
    sa.Column('id', sa.INTEGER(), nullable=False),
    sa.Column('quiz_score', sa.INTEGER(), nullable=True),
    sa.Column('created_at', sa.DATETIME(), nullable=True),
    sa.PrimaryKeyConstraint('id')
    )
    op.drop_table('quizresult')
    op.drop_table('user')
    # ### end Alembic commands ###
